</xml version="1.0"?>
<robot name="my_robot">

    <material name="gray">
        <color rgba="0.7 0.7 0.7 1"/>
    </material>

    <material name="green">
        <color rgba="0 0.6 0 1"/>
    </material>

    <material name="white">
        <color rgba="1 1 1 1"/>
    </material>

<link name="base_link">
    <visual>
    <origin rpy="0 0 0" xyz="0 0 0.0508"/>
    <geometry>
        <box size="0.30479999999999996 0.2032 0.1016"/>
    </geometry>
    <material name="blue">
        <color rgba="0 0 .8 1"/>
    </material>
    </visual>
    <collision>
     <geometry>
         <box size="0.30479999999999996 0.2032 0.1016"/>
     </geometry>
    </collision>
    <inertial>
        <mass value="10"/>
        <inertia ixx="1e-3" ixy="0.0" ixz="0.0" iyy="1e-3" iyz="0.0" izz="1e-3"/>
    </inertial>
</link>

    <link name="back_left_wheel">
        <visual>
            <geometry>
                <cylinder radius="0.041275" length="0.03175"/>
            </geometry>
            <origin xyz="0 0 0" rpy="1.57 0 0"/>
            <material name="gray"/>
        </visual>
    </link>

    <link name="back_right_wheel">
        <visual>
            <geometry>
            <cylinder radius="0.041275" length="0.03175"/>
            </geometry>
            <origin xyz="0 0 0" rpy="1.5707963267948966 0 0"/>
            <material name="gray"/>
        </visual>
    </link>

    <link name="front_left_wheel">
        <visual>
            <geometry>
                <cylinder radius="0.041275" length="0.03175"/>
            </geometry>
            <origin xyz="0 0 0" rpy="1.5707963267948966 0 0"/>
            <material name="gray"/>
        </visual>
    </link>

    <link name="front_right_wheel">
        <visual>
            <geometry>
                <cylinder radius="0.041275" length="0.03175"/>
            </geometry>
            <origin xyz="0 0 0" rpy="1.5707963267948966 0 0"/>
            <material name="gray"/>
        </visual>
    </link>

    <joint name="back_left_wheel_joint" type="continuous">
        <parent link="base_link"/>
        <child link="back_left_wheel"/>
        <origin xyz="-0.1016 -0.127 0" rpy="0 0 0"/>
        <axis xyz="0 1 0"/>
    </joint>

    <joint name="back_right_wheel_joint" type="continuous">
        <parent link="base_link"/>
        <child link="back_right_wheel"/>
        <origin xyz="-0.1016 0.127 0" rpy="0 0 0"/>
        <axis xyz="0 1 0"/>
    </joint>

    <joint name="front_left_wheel_joint" type="continuous">
        <parent link="base_link"/>
        <child link="front_left_wheel"/>
        <origin xyz="0.1016 -0.127 0" rpy="0 0 0"/>
        <axis xyz="0 1 0"/>
    </joint>

    <joint name="front_right_wheel_joint" type="continuous">
        <parent link="base_link"/>
        <child link="front_right_wheel"/>
        <origin xyz="0.1016 0.127 0" rpy="0 0 0"/>
        <axis xyz="0 1 0"/>
    </joint>
</robot>
