<?xml version="1.0"?>
<robot xmlns:xacro="http://www.ros.org/wiki/xacro" name="my_robot">
    
    <xacro:property name="wheel_radius" value="0.041275"/>
    <xacro:property name="wheel_length" value="0.03175"/>
    <xacro:property name="wheel_mass" value="0.5"/>
    <xacro:property name="base_length" value="0.3048"/>
    <xacro:property name="base_width" value="0.2032"/>
    <xacro:property name="base_height" value="0.1016"/>
    <xacro:property name="base_mass" value="10"/>
    <xacro:property name="wheel_offset_x" value="0.1016"/>
    <xacro:property name="wheel_offset_y" value="0.127"/>
    
    <material name="gray">
        <color rgba="0.7 0.7 0.7 1"/>
    </material>
    
    <material name="green">
        <color rgba="0 0.6 0 1"/>
    </material>
    
    <material name="white">
        <color rgba="1 1 1 1"/>
    </material>
    
    <material name="blue">
        <color rgba="0 0 0.8 1"/>
    </material>
    
    <xacro:macro name="wheel_link" params="prefix">
        <link name="${prefix}_wheel">
            <visual>
                <geometry>
                    <cylinder radius="${wheel_radius}" length="${wheel_length}"/>
                </geometry>
                <origin xyz="0 0 0" rpy="1.57 0 0"/>
                <material name="gray"/>
                </visual>
                <collision>
                <geometry>
                    <cylinder radius="${wheel_radius}" length="${wheel_length}"/>
                </geometry>
                <origin xyz="0 0 0" rpy="1.57 0 0"/>
                </collision>
                <inertial>
                    <mass value="${wheel_mass}"/>
                    <origin xyz="0 0 0"/>
                    <inertia ixx="1e-4" ixy="0.0" ixz="0.0" iyy="1e-4" iyz="0.0" izz="1e-4"/>
            </inertial>
        </link>
    </xacro:macro>
    
    <xacro:macro name="wheel_joint" params="name parent child x y">
        <joint name="${name}" type="continuous">
            <parent link="${parent}"/>
            <child link="${child}"/>
            <origin xyz="${x} ${y} 0" rpy="0 0 0"/>
            <axis xyz="0 1 0"/>
        </joint>
    </xacro:macro>
    
    <xacro:macro name="my_robot" params="">
        <link name="base_link">
            <visual>
                <origin rpy="0 0 0" xyz="0 0 ${base_height / 2}"/>
                <geometry>
                    <box size="${base_length} ${base_width} ${base_height}"/>
                </geometry>
                <material name="blue"/>
            </visual>
            <collision>
                <geometry>
                    <box size="${base_length} ${base_width} ${base_height}"/>
                </geometry>
                <origin xyz="0 0 ${base_height / 2}" rpy="0 0 0"/>
            </collision>
            <inertial>
            <mass value="${base_mass}"/>
            <origin xyz="0 0 ${base_height / 2}"/>
            <inertia ixx="1e-3" ixy="0.0" ixz="0.0" iyy="1e-3" iyz="0.0" izz="1e-3"/>
        </inertial>
    </link>
    
    <xacro:wheel_link prefix="back_left"/>
    <xacro:wheel_link prefix="back_right"/>
    <xacro:wheel_link prefix="front_left"/>
    <xacro:wheel_link prefix="front_right"/>

    <xacro:wheel_joint name="back_left_wheel_joint" parent="base_link" child="back_left_wheel" x="-${wheel_offset_x}" y="-${wheel_offset_y}"/>
    <xacro:wheel_joint name="back_right_wheel_joint" parent="base_link" child="back_right_wheel" x="-${wheel_offset_x}" y="${wheel_offset_y}"/>
    <xacro:wheel_joint name="front_left_wheel_joint" parent="base_link" child="front_left_wheel" x="${wheel_offset_x}" y="-${wheel_offset_y}"/>
    <xacro:wheel_joint name="front_right_wheel_joint" parent="base_link" child="front_right_wheel" x="${wheel_offset_x}" y="${wheel_offset_y}"/>
    </xacro:macro>

    <xacro:my_robot/>
</robot>
